Workbook

Sheet Dashboard
A1: Myntra Social Media Intelligence Dashboard
A2: Posts: 01 Jun 2024 to 14 May 2025 (300 posts) | Weekly follower data: 03 Jun 2024 to 12 May 2025 | Ad spend shown in the units supplied (currency not stated)
B4: Platform | C4: All | E4: Campaign | F4: All | I4: Yellow cells are dropdown filters. Platform filters posts and weekly data; Campaign filters posts only.
A6: POSTS | C6: IMPRESSIONS | E6: AVG POST ENGAGEMENT RATE | G6: POOLED ENGAGEMENT RATE | I6: CLICK-THROUGH RATE | K6: AD SPEND | M6: NET FOLLOWERS ADDED
A7: =COUNTIFS(Data_Posts!$B$2:$B$301,Calc!$B$1,Data_Posts!$N$2:$N$301,Calc!$B$2) -> 300 | C7: =SUMIFS(Data_Posts!$I$2:$I$301,Data_Posts!$B$2:$B$301,Calc!$B$1,Data_Posts!$N$2:$N$301,Calc!$B$2) -> 10394153 | E7: =IFERROR(AVERAGEIFS(Data_Posts!$P$2:$P$301,Data_Posts!$B$2:$B$301,Calc!$B$1,Data_Posts!$N$2:$N$301,Calc!$B$2),0) -> 0.14828272 | G7: =IFERROR(SUMIFS(Data_Posts!$O$2:$O$301,Data_Posts!$B$2:$B$301,Calc!$B$1,Data_Posts!$N$2:$N$301,Calc!$B$2)/SUMIFS(Data_Posts!$I$2:$I$301,Data_Posts!$B$2:$B$301,Calc!$B$1,Data_Posts!$N$2:$N$301,Calc!$B$2),0) -> 0.09984142 | I7: =IFERROR(SUMIFS(Data_Posts!$K$2:$K$301,Data_Posts!$B$2:$B$301,Calc!$B$1,Data_Posts!$N$2:$N$301,Calc!$B$2)/SUMIFS(Data_Posts!$I$2:$I$301,Data_Posts!$B$2:$B$301,Calc!$B$1,Data_Posts!$N$2:$N$301,Calc!$B$2),0) -> 0.0043645692 | K7: =SUMIFS(Data_Weekly!$G$2:$G$201,Data_Weekly!$B$2:$B$201,Calc!$B$1) -> 4832916 | M7: =SUMIFS(Data_Weekly!$H$2:$H$201,Data_Weekly!$B$2:$B$201,Calc!$B$1) -> 160105
A8: filtered | C8: filtered | E8: mean of per-post rates | G8: total engagement / impressions | I8: clicks / impressions | K8: weekly data, platform filter | M8: new minus unfollows
A10: Key findings (full dataset, static text, does not change with the filters)
A11: PLATFORMS: Instagram has the highest average post engagement rate (19.3%; others 12.2% to 14.4%) and Instagram added the most net followers (48,004). Facebook receives the most ad spend (1,379,539) but turns it into only 25.8 net followers per 1,000 spent, versus 41.2 on Instagram.
A12: CONTENT: Story posts have the best average engagement rate (18.4%) and Text posts the worst (11.8%). The strongest platform/format combos are Instagram Reels (26.0%) and Instagram Stories (24.6%). Each combo has only about 12 posts, so treat this as directional.
A13: AD SPEND: weekly ad spend barely moves follower growth. Correlation with net adds is -0.06 for all platforms combined and 0.03 to 0.23 by platform. In this data, spending more in a week does not reliably buy more followers.
A14: HASHTAGS: #StyleWithMyntra has the highest average engagement rate (15.6%) and #StyleWithMyntra is the most used (104 posts). The gap between the best and worst hashtag (#FashionDeals) is only 2.0 percentage points, so hashtag choice is a minor lever compared with platform and format.
A15: CAMPAIGNS: EndOfSeasonSale generated the most engagements (295,774); FashionUpgrade the most per 1,000 budget (1,657); StyleRevolution added the most followers per 1,000 budget during its dates (86.2) and StyleRevolution has the highest average engagement rate (15.8%).
A16: CAUTION: campaign tags on posts do not line up with campaign dates (EndOfSeasonSale-tagged posts run Jun 2024 to Apr 2025, the campaign ran 10 Jun to 5 Jul 2024), so post-based and date-window campaign figures measure different things. A few tiny-impression posts have rates above 100% (max 181%), which inflates averages; the pooled rate is shown beside it.
A18: 1. Platform comparison
A19: Platform | B19: Posts | C19: Impressions | D19: Avg Post Engagement Rate | E19: Pooled Engagement Rate | F19: Clicks | G19: CTR | H19: Ad Spend | I19: Net Followers Added | J19: Net Followers per 1,000 Ad Spend
A20: Facebook | B20: =COUNTIFS(Data_Posts!$B$2:$B$301,$A20,Data_Posts!$N$2:$N$301,Calc!$B$2) -> 83 | C20: =SUMIFS(Data_Posts!$I$2:$I$301,Data_Posts!$B$2:$B$301,$A20,Data_Posts!$N$2:$N$301,Calc!$B$2) -> 3239154 | D20: =IFERROR(AVERAGEIFS(Data_Posts!$P$2:$P$301,Data_Posts!$B$2:$B$301,$A20,Data_Posts!$N$2:$N$301,Calc!$B$2),0) -> 0.1219729 | E20: =IFERROR(SUMIFS(Data_Posts!$O$2:$O$301,Data_Posts!$B$2:$B$301,$A20,Data_Posts!$N$2:$N$301,Calc!$B$2)/C20,0) -> 0.0942351 | F20: =SUMIFS(Data_Posts!$K$2:$K$301,Data_Posts!$B$2:$B$301,$A20,Data_Posts!$N$2:$N$301,Calc!$B$2) -> 12184 | G20: =IFERROR(F20/C20,0) -> 0.003761476 | H20: =SUMIFS(Data_Weekly!$G$2:$G$201,Data_Weekly!$B$2:$B$201,$A20) -> 1379539 | I20: =SUMIFS(Data_Weekly!$H$2:$H$201,Data_Weekly!$B$2:$B$201,$A20) -> 35557 | J20: =IFERROR(I20/H20*1000,0) -> 25.774552
A21: Instagram | B21: =COUNTIFS(Data_Posts!$B$2:$B$301,$A21,Data_Posts!$N$2:$N$301,Calc!$B$2) -> 79 | C21: =SUMIFS(Data_Posts!$I$2:$I$301,Data_Posts!$B$2:$B$301,$A21,Data_Posts!$N$2:$N$301,Calc!$B$2) -> 2325756 | D21: =IFERROR(AVERAGEIFS(Data_Posts!$P$2:$P$301,Data_Posts!$B$2:$B$301,$A21,Data_Posts!$N$2:$N$301,Calc!$B$2),0) -> 0.19329258 | E21: =IFERROR(SUMIFS(Data_Posts!$O$2:$O$301,Data_Posts!$B$2:$B$301,$A21,Data_Posts!$N$2:$N$301,Calc!$B$2)/C21,0) -> 0.11333046 | F21: =SUMIFS(Data_Posts!$K$2:$K$301,Data_Posts!$B$2:$B$301,$A21,Data_Posts!$N$2:$N$301,Calc!$B$2) -> 12078 | G21: =IFERROR(F21/C21,0) -> 0.0051931501 | H21: =SUMIFS(Data_Weekly!$G$2:$G$201,Data_Weekly!$B$2:$B$201,$A21) -> 1164373 | I21: =SUMIFS(Data_Weekly!$H$2:$H$201,Data_Weekly!$B$2:$B$201,$A21) -> 48004 | J21: =IFERROR(I21/H21*1000,0) -> 41.227339
A22: Twitter | B22: =COUNTIFS(Data_Posts!$B$2:$B$301,$A22,Data_Posts!$N$2:$N$301,Calc!$B$2) -> 79 | C22: =SUMIFS(Data_Posts!$I$2:$I$301,Data_Posts!$B$2:$B$301,$A22,Data_Posts!$N$2:$N$301,Calc!$B$2) -> 2560836 | D22: =IFERROR(AVERAGEIFS(Data_Posts!$P$2:$P$301,Data_Posts!$B$2:$B$301,$A22,Data_Posts!$N$2:$N$301,Calc!$B$2),0) -> 0.14368407 | E22: =IFERROR(SUMIFS(Data_Posts!$O$2:$O$301,Data_Posts!$B$2:$B$301,$A22,Data_Posts!$N$2:$N$301,Calc!$B$2)/C22,0) -> 0.099969307 | F22: =SUMIFS(Data_Posts!$K$2:$K$301,Data_Posts!$B$2:$B$301,$A22,Data_Posts!$N$2:$N$301,Calc!$B$2) -> 12398 | G22: =IFERROR(F22/C22,0) -> 0.0048413877 | H22: =SUMIFS(Data_Weekly!$G$2:$G$201,Data_Weekly!$B$2:$B$201,$A22) -> 1060357 | I22: =SUMIFS(Data_Weekly!$H$2:$H$201,Data_Weekly!$B$2:$B$201,$A22) -> 41177 | J22: =IFERROR(I22/H22*1000,0) -> 38.833148
A23: YouTube | B23: =COUNTIFS(Data_Posts!$B$2:$B$301,$A23,Data_Posts!$N$2:$N$301,Calc!$B$2) -> 59 | C23: =SUMIFS(Data_Posts!$I$2:$I$301,Data_Posts!$B$2:$B$301,$A23,Data_Posts!$N$2:$N$301,Calc!$B$2) -> 2268407 | D23: =IFERROR(AVERAGEIFS(Data_Posts!$P$2:$P$301,Data_Posts!$B$2:$B$301,$A23,Data_Posts!$N$2:$N$301,Calc!$B$2),0) -> 0.13118494 | E23: =IFERROR(SUMIFS(Data_Posts!$O$2:$O$301,Data_Posts!$B$2:$B$301,$A23,Data_Posts!$N$2:$N$301,Calc!$B$2)/C23,0) -> 0.093872484 | F23: =SUMIFS(Data_Posts!$K$2:$K$301,Data_Posts!$B$2:$B$301,$A23,Data_Posts!$N$2:$N$301,Calc!$B$2) -> 8706 | G23: =IFERROR(F23/C23,0) -> 0.0038379356 | H23: =SUMIFS(Data_Weekly!$G$2:$G$201,Data_Weekly!$B$2:$B$201,$A23) -> 1228647 | I23: =SUMIFS(Data_Weekly!$H$2:$H$201,Data_Weekly!$B$2:$B$201,$A23) -> 35367 | J23: =IFERROR(I23/H23*1000,0) -> 28.785322
A24: Post columns follow the Campaign filter. Ad spend and follower columns come from the weekly summary, which has no campaign field, so the Campaign filter does not change them.
A42: 2. Content type performance
A43: Content Type | B43: Posts | C43: Avg Post Engagement Rate | D43: Pooled Engagement Rate | E43: Avg Likes | F43: Avg Shares | G43: Avg Comments | H43: Avg Clicks | J43: Avg engagement rate | K43: Facebook | L43: Instagram | M43: Twitter | N43: YouTube
A44: Carousel | B44: =COUNTIFS(Data_Posts!$D$2:$D$301,$A44,Data_Posts!$B$2:$B$301,Calc!$B$1,Data_Posts!$N$2:$N$301,Calc!$B$2) -> 59 | C44: =IFERROR(AVERAGEIFS(Data_Posts!$P$2:$P$301,Data_Posts!$D$2:$D$301,$A44,Data_Posts!$B$2:$B$301,Calc!$B$1,Data_Posts!$N$2:$N$301,Calc!$B$2),0) -> 0.1481492 | D44: =IFERROR(SUMIFS(Data_Posts!$O$2:$O$301,Data_Posts!$D$2:$D$301,$A44,Data_Posts!$B$2:$B$301,Calc!$B$1,Data_Posts!$N$2:$N$301,Calc!$B$2)/SUMIFS(Data_Posts!$I$2:$I$301,Data_Posts!$D$2:$D$301,$A44,Data_Posts!$B$2:$B$301,Calc!$B$1,Data_Posts!$N$2:$N$301,Calc!$B$2),0) -> 0.095982803 | E44: =IFERROR(AVERAGEIFS(Data_Posts!$F$2:$F$301,Data_Posts!$D$2:$D$301,$A44,Data_Posts!$B$2:$B$301,Calc!$B$1,Data_Posts!$N$2:$N$301,Calc!$B$2),0) -> 2745.7458 | F44: =IFERROR(AVERAGEIFS(Data_Posts!$G$2:$G$301,Data_Posts!$D$2:$D$301,$A44,Data_Posts!$B$2:$B$301,Calc!$B$1,Data_Posts!$N$2:$N$301,Calc!$B$2),0) -> 448.66102 | G44: =IFERROR(AVERAGEIFS(Data_Posts!$H$2:$H$301,Data_Posts!$D$2:$D$301,$A44,Data_Posts!$B$2:$B$301,Calc!$B$1,Data_Posts!$N$2:$N$301,Calc!$B$2),0) -> 245.89831 | H44: =IFERROR(AVERAGEIFS(Data_Posts!$K$2:$K$301,Data_Posts!$D$2:$D$301,$A44,Data_Posts!$B$2:$B$301,Calc!$B$1,Data_Posts!$N$2:$N$301,Calc!$B$2),0) -> 156.81356 | J44: Carousel | K44: =IFERROR(AVERAGEIFS(Data_Posts!$P$2:$P$301,Data_Posts!$D$2:$D$301,$J44,Data_Posts!$B$2:$B$301,K$43,Data_Posts!$N$2:$N$301,Calc!$B$2),0) -> 0.1182059 | L44: =IFERROR(AVERAGEIFS(Data_Posts!$P$2:$P$301,Data_Posts!$D$2:$D$301,$J44,Data_Posts!$B$2:$B$301,L$43,Data_Posts!$N$2:$N$301,Calc!$B$2),0) -> 0.1443986 | M44: =IFERROR(AVERAGEIFS(Data_Posts!$P$2:$P$301,Data_Posts!$D$2:$D$301,$J44,Data_Posts!$B$2:$B$301,M$43,Data_Posts!$N$2:$N$301,Calc!$B$2),0) -> 0.15972488 | N44: =IFERROR(AVERAGEIFS(Data_Posts!$P$2:$P$301,Data_Posts!$D$2:$D$301,$J44,Data_Posts!$B$2:$B$301,N$43,Data_Posts!$N$2:$N$301,Calc!$B$2),0) -> 0.17416554
A45: Image | B45: =COUNTIFS(Data_Posts!$D$2:$D$301,$A45,Data_Posts!$B$2:$B$301,Calc!$B$1,Data_Posts!$N$2:$N$301,Calc!$B$2) -> 63 | C45: =IFERROR(AVERAGEIFS(Data_Posts!$P$2:$P$301,Data_Posts!$D$2:$D$301,$A45,Data_Posts!$B$2:$B$301,Calc!$B$1,Data_Posts!$N$2:$N$301,Calc!$B$2),0) -> 0.13687494 | D45: =IFERROR(SUMIFS(Data_Posts!$O$2:$O$301,Data_Posts!$D$2:$D$301,$A45,Data_Posts!$B$2:$B$301,Calc!$B$1,Data_Posts!$N$2:$N$301,Calc!$B$2)/SUMIFS(Data_Posts!$I$2:$I$301,Data_Posts!$D$2:$D$301,$A45,Data_Posts!$B$2:$B$301,Calc!$B$1,Data_Posts!$N$2:$N$301,Calc!$B$2),0) -> 0.097082482 | E45: =IFERROR(AVERAGEIFS(Data_Posts!$F$2:$F$301,Data_Posts!$D$2:$D$301,$A45,Data_Posts!$B$2:$B$301,Calc!$B$1,Data_Posts!$N$2:$N$301,Calc!$B$2),0) -> 2753.4603 | F45: =IFERROR(AVERAGEIFS(Data_Posts!$G$2:$G$301,Data_Posts!$D$2:$D$301,$A45,Data_Posts!$B$2:$B$301,Calc!$B$1,Data_Posts!$N$2:$N$301,Calc!$B$2),0) -> 470 | G45: =IFERROR(AVERAGEIFS(Data_Posts!$H$2:$H$301,Data_Posts!$D$2:$D$301,$A45,Data_Posts!$B$2:$B$301,Calc!$B$1,Data_Posts!$N$2:$N$301,Calc!$B$2),0) -> 259.55556 | H45: =IFERROR(AVERAGEIFS(Data_Posts!$K$2:$K$301,Data_Posts!$D$2:$D$301,$A45,Data_Posts!$B$2:$B$301,Calc!$B$1,Data_Posts!$N$2:$N$301,Calc!$B$2),0) -> 163.5873 | J45: Image | K45: =IFERROR(AVERAGEIFS(Data_Posts!$P$2:$P$301,Data_Posts!$D$2:$D$301,$J45,Data_Posts!$B$2:$B$301,K$43,Data_Posts!$N$2:$N$301,Calc!$B$2),0) -> 0.11892683 | L45: =IFERROR(AVERAGEIFS(Data_Posts!$P$2:$P$301,Data_Posts!$D$2:$D$301,$J45,Data_Posts!$B$2:$B$301,L$43,Data_Posts!$N$2:$N$301,Calc!$B$2),0) -> 0.14929862 | M45: =IFERROR(AVERAGEIFS(Data_Posts!$P$2:$P$301,Data_Posts!$D$2:$D$301,$J45,Data_Posts!$B$2:$B$301,M$43,Data_Posts!$N$2:$N$301,Calc!$B$2),0) -> 0.14756648 | N45: =IFERROR(AVERAGEIFS(Data_Posts!$P$2:$P$301,Data_Posts!$D$2:$D$301,$J45,Data_Posts!$B$2:$B$301,N$43,Data_Posts!$N$2:$N$301,Calc!$B$2),0) -> 0.15035568
A46: Reel | B46: =COUNTIFS(Data_Posts!$D$2:$D$301,$A46,Data_Posts!$B$2:$B$301,Calc!$B$1,Data_Posts!$N$2:$N$301,Calc!$B$2) -> 47 | C46: =IFERROR(AVERAGEIFS(Data_Posts!$P$2:$P$301,Data_Posts!$D$2:$D$301,$A46,Data_Posts!$B$2:$B$301,Calc!$B$1,Data_Posts!$N$2:$N$301,Calc!$B$2),0) -> 0.15615682 | D46: =IFERROR(SUMIFS(Data_Posts!$O$2:$O$301,Data_Posts!$D$2:$D$301,$A46,Data_Posts!$B$2:$B$301,Calc!$B$1,Data_Posts!$N$2:$N$301,Calc!$B$2)/SUMIFS(Data_Posts!$I$2:$I$301,Data_Posts!$D$2:$D$301,$A46,Data_Posts!$B$2:$B$301,Calc!$B$1,Data_Posts!$N$2:$N$301,Calc!$B$2),0) -> 0.098120168 | E46: =IFERROR(AVERAGEIFS(Data_Posts!$F$2:$F$301,Data_Posts!$D$2:$D$301,$A46,Data_Posts!$B$2:$B$301,Calc!$B$1,Data_Posts!$N$2:$N$301,Calc!$B$2),0) -> 2722.234 | F46: =IFERROR(AVERAGEIFS(Data_Posts!$G$2:$G$301,Data_Posts!$D$2:$D$301,$A46,Data_Posts!$B$2:$B$301,Calc!$B$1,Data_Posts!$N$2:$N$301,Calc!$B$2),0) -> 493.6383 | G46: =IFERROR(AVERAGEIFS(Data_Posts!$H$2:$H$301,Data_Posts!$D$2:$D$301,$A46,Data_Posts!$B$2:$B$301,Calc!$B$1,Data_Posts!$N$2:$N$301,Calc!$B$2),0) -> 240.85106 | H46: =IFERROR(AVERAGEIFS(Data_Posts!$K$2:$K$301,Data_Posts!$D$2:$D$301,$A46,Data_Posts!$B$2:$B$301,Calc!$B$1,Data_Posts!$N$2:$N$301,Calc!$B$2),0) -> 152.65957 | J46: Reel | K46: =IFERROR(AVERAGEIFS(Data_Posts!$P$2:$P$301,Data_Posts!$D$2:$D$301,$J46,Data_Posts!$B$2:$B$301,K$43,Data_Posts!$N$2:$N$301,Calc!$B$2),0) -> 0.10810248 | L46: =IFERROR(AVERAGEIFS(Data_Posts!$P$2:$P$301,Data_Posts!$D$2:$D$301,$J46,Data_Posts!$B$2:$B$301,L$43,Data_Posts!$N$2:$N$301,Calc!$B$2),0) -> 0.26004033 | M46: =IFERROR(AVERAGEIFS(Data_Posts!$P$2:$P$301,Data_Posts!$D$2:$D$301,$J46,Data_Posts!$B$2:$B$301,M$43,Data_Posts!$N$2:$N$301,Calc!$B$2),0) -> 0.12428082 | N46: =IFERROR(AVERAGEIFS(Data_Posts!$P$2:$P$301,Data_Posts!$D$2:$D$301,$J46,Data_Posts!$B$2:$B$301,N$43,Data_Posts!$N$2:$N$301,Calc!$B$2),0) -> 0.11688584
A47: Story | B47: =COUNTIFS(Data_Posts!$D$2:$D$301,$A47,Data_Posts!$B$2:$B$301,Calc!$B$1,Data_Posts!$N$2:$N$301,Calc!$B$2) -> 46 | C47: =IFERROR(AVERAGEIFS(Data_Posts!$P$2:$P$301,Data_Posts!$D$2:$D$301,$A47,Data_Posts!$B$2:$B$301,Calc!$B$1,Data_Posts!$N$2:$N$301,Calc!$B$2),0) -> 0.18425775 | D47: =IFERROR(SUMIFS(Data_Posts!$O$2:$O$301,Data_Posts!$D$2:$D$301,$A47,Data_Posts!$B$2:$B$301,Calc!$B$1,Data_Posts!$N$2:$N$301,Calc!$B$2)/SUMIFS(Data_Posts!$I$2:$I$301,Data_Posts!$D$2:$D$301,$A47,Data_Posts!$B$2:$B$301,Calc!$B$1,Data_Posts!$N$2:$N$301,Calc!$B$2),0) -> 0.10843167 | E47: =IFERROR(AVERAGEIFS(Data_Posts!$F$2:$F$301,Data_Posts!$D$2:$D$301,$A47,Data_Posts!$B$2:$B$301,Calc!$B$1,Data_Posts!$N$2:$N$301,Calc!$B$2),0) -> 2706.2609 | F47: =IFERROR(AVERAGEIFS(Data_Posts!$G$2:$G$301,Data_Posts!$D$2:$D$301,$A47,Data_Posts!$B$2:$B$301,Calc!$B$1,Data_Posts!$N$2:$N$301,Calc!$B$2),0) -> 520.76087 | G47: =IFERROR(AVERAGEIFS(Data_Posts!$H$2:$H$301,Data_Posts!$D$2:$D$301,$A47,Data_Posts!$B$2:$B$301,Calc!$B$1,Data_Posts!$N$2:$N$301,Calc!$B$2),0) -> 263.19565 | H47: =IFERROR(AVERAGEIFS(Data_Posts!$K$2:$K$301,Data_Posts!$D$2:$D$301,$A47,Data_Posts!$B$2:$B$301,Calc!$B$1,Data_Posts!$N$2:$N$301,Calc!$B$2),0) -> 131.69565 | J47: Story | K47: =IFERROR(AVERAGEIFS(Data_Posts!$P$2:$P$301,Data_Posts!$D$2:$D$301,$J47,Data_Posts!$B$2:$B$301,K$43,Data_Posts!$N$2:$N$301,Calc!$B$2),0) -> 0.15898978 | L47: =IFERROR(AVERAGEIFS(Data_Posts!$P$2:$P$301,Data_Posts!$D$2:$D$301,$J47,Data_Posts!$B$2:$B$301,L$43,Data_Posts!$N$2:$N$301,Calc!$B$2),0) -> 0.24558274 | M47: =IFERROR(AVERAGEIFS(Data_Posts!$P$2:$P$301,Data_Posts!$D$2:$D$301,$J47,Data_Posts!$B$2:$B$301,M$43,Data_Posts!$N$2:$N$301,Calc!$B$2),0) -> 0.18859717 | N47: =IFERROR(AVERAGEIFS(Data_Posts!$P$2:$P$301,Data_Posts!$D$2:$D$301,$J47,Data_Posts!$B$2:$B$301,N$43,Data_Posts!$N$2:$N$301,Calc!$B$2),0) -> 0.09496533
A48: Text | B48: =COUNTIFS(Data_Posts!$D$2:$D$301,$A48,Data_Posts!$B$2:$B$301,Calc!$B$1,Data_Posts!$N$2:$N$301,Calc!$B$2) -> 42 | C48: =IFERROR(AVERAGEIFS(Data_Posts!$P$2:$P$301,Data_Posts!$D$2:$D$301,$A48,Data_Posts!$B$2:$B$301,Calc!$B$1,Data_Posts!$N$2:$N$301,Calc!$B$2),0) -> 0.11750674 | D48: =IFERROR(SUMIFS(Data_Posts!$O$2:$O$301,Data_Posts!$D$2:$D$301,$A48,Data_Posts!$B$2:$B$301,Calc!$B$1,Data_Posts!$N$2:$N$301,Calc!$B$2)/SUMIFS(Data_Posts!$I$2:$I$301,Data_Posts!$D$2:$D$301,$A48,Data_Posts!$B$2:$B$301,Calc!$B$1,Data_Posts!$N$2:$N$301,Calc!$B$2),0) -> 0.098262835 | E48: =IFERROR(AVERAGEIFS(Data_Posts!$F$2:$F$301,Data_Posts!$D$2:$D$301,$A48,Data_Posts!$B$2:$B$301,Calc!$B$1,Data_Posts!$N$2:$N$301,Calc!$B$2),0) -> 2773.7143 | F48: =IFERROR(AVERAGEIFS(Data_Posts!$G$2:$G$301,Data_Posts!$D$2:$D$301,$A48,Data_Posts!$B$2:$B$301,Calc!$B$1,Data_Posts!$N$2:$N$301,Calc!$B$2),0) -> 445.07143 | G48: =IFERROR(AVERAGEIFS(Data_Posts!$H$2:$H$301,Data_Posts!$D$2:$D$301,$A48,Data_Posts!$B$2:$B$301,Calc!$B$1,Data_Posts!$N$2:$N$301,Calc!$B$2),0) -> 244.88095 | H48: =IFERROR(AVERAGEIFS(Data_Posts!$K$2:$K$301,Data_Posts!$D$2:$D$301,$A48,Data_Posts!$B$2:$B$301,Calc!$B$1,Data_Posts!$N$2:$N$301,Calc!$B$2),0) -> 163.40476 | J48: Text | K48: =IFERROR(AVERAGEIFS(Data_Posts!$P$2:$P$301,Data_Posts!$D$2:$D$301,$J48,Data_Posts!$B$2:$B$301,K$43,Data_Posts!$N$2:$N$301,Calc!$B$2),0) -> 0.10743951 | L48: =IFERROR(AVERAGEIFS(Data_Posts!$P$2:$P$301,Data_Posts!$D$2:$D$301,$J48,Data_Posts!$B$2:$B$301,L$43,Data_Posts!$N$2:$N$301,Calc!$B$2),0) -> 0.12920449 | M48: =IFERROR(AVERAGEIFS(Data_Posts!$P$2:$P$301,Data_Posts!$D$2:$D$301,$J48,Data_Posts!$B$2:$B$301,M$43,Data_Posts!$N$2:$N$301,Calc!$B$2),0) -> 0.12088973 | N48: =IFERROR(AVERAGEIFS(Data_Posts!$P$2:$P$301,Data_Posts!$D$2:$D$301,$J48,Data_Posts!$B$2:$B$301,N$43,Data_Posts!$N$2:$N$301,Calc!$B$2),0) -> 0.11459218
A49: Video | B49: =COUNTIFS(Data_Posts!$D$2:$D$301,$A49,Data_Posts!$B$2:$B$301,Calc!$B$1,Data_Posts!$N$2:$N$301,Calc!$B$2) -> 43 | C49: =IFERROR(AVERAGEIFS(Data_Posts!$P$2:$P$301,Data_Posts!$D$2:$D$301,$A49,Data_Posts!$B$2:$B$301,Calc!$B$1,Data_Posts!$N$2:$N$301,Calc!$B$2),0) -> 0.14814844 | D49: =IFERROR(SUMIFS(Data_Posts!$O$2:$O$301,Data_Posts!$D$2:$D$301,$A49,Data_Posts!$B$2:$B$301,Calc!$B$1,Data_Posts!$N$2:$N$301,Calc!$B$2)/SUMIFS(Data_Posts!$I$2:$I$301,Data_Posts!$D$2:$D$301,$A49,Data_Posts!$B$2:$B$301,Calc!$B$1,Data_Posts!$N$2:$N$301,Calc!$B$2),0) -> 0.10473608 | E49: =IFERROR(AVERAGEIFS(Data_Posts!$F$2:$F$301,Data_Posts!$D$2:$D$301,$A49,Data_Posts!$B$2:$B$301,Calc!$B$1,Data_Posts!$N$2:$N$301,Calc!$B$2),0) -> 2688.2558 | F49: =IFERROR(AVERAGEIFS(Data_Posts!$G$2:$G$301,Data_Posts!$D$2:$D$301,$A49,Data_Posts!$B$2:$B$301,Calc!$B$1,Data_Posts!$N$2:$N$301,Calc!$B$2),0) -> 488.25581 | G49: =IFERROR(AVERAGEIFS(Data_Posts!$H$2:$H$301,Data_Posts!$D$2:$D$301,$A49,Data_Posts!$B$2:$B$301,Calc!$B$1,Data_Posts!$N$2:$N$301,Calc!$B$2),0) -> 239.04651 | H49: =IFERROR(AVERAGEIFS(Data_Posts!$K$2:$K$301,Data_Posts!$D$2:$D$301,$A49,Data_Posts!$B$2:$B$301,Calc!$B$1,Data_Posts!$N$2:$N$301,Calc!$B$2),0) -> 132.83721 | J49: Video | K49: =IFERROR(AVERAGEIFS(Data_Posts!$P$2:$P$301,Data_Posts!$D$2:$D$301,$J49,Data_Posts!$B$2:$B$301,K$43,Data_Posts!$N$2:$N$301,Calc!$B$2),0) -> 0.12899654 | L49: =IFERROR(AVERAGEIFS(Data_Posts!$P$2:$P$301,Data_Posts!$D$2:$D$301,$J49,Data_Posts!$B$2:$B$301,L$43,Data_Posts!$N$2:$N$301,Calc!$B$2),0) -> 0.20623961 | M49: =IFERROR(AVERAGEIFS(Data_Posts!$P$2:$P$301,Data_Posts!$D$2:$D$301,$J49,Data_Posts!$B$2:$B$301,M$43,Data_Posts!$N$2:$N$301,Calc!$B$2),0) -> 0.11980877 | N49: =IFERROR(AVERAGEIFS(Data_Posts!$P$2:$P$301,Data_Posts!$D$2:$D$301,$J49,Data_Posts!$B$2:$B$301,N$43,Data_Posts!$N$2:$N$301,Calc!$B$2),0) -> 0.12968338
A50: Left table follows both filters. The heatmap (content type x platform) follows the Campaign filter only; each cell holds roughly 12 posts, so read it as directional.
A68: 3. Hashtag performance
A69: Hashtag | B69: Posts Using It | C69: Avg Post Engagement Rate | D69: Avg Clicks per Post | E69: Share of Hashtag Uses
A70: #FashionDeals | B70: =COUNTIFS(Data_Hashtags!$C$2:$C$457,$A70,Data_Hashtags!$B$2:$B$457,Calc!$B$1,Data_Hashtags!$D$2:$D$457,Calc!$B$2) -> 80 | C70: =IFERROR(AVERAGEIFS(Data_Hashtags!$E$2:$E$457,Data_Hashtags!$C$2:$C$457,$A70,Data_Hashtags!$B$2:$B$457,Calc!$B$1,Data_Hashtags!$D$2:$D$457,Calc!$B$2),0) -> 0.13661099 | D70: =IFERROR(AVERAGEIFS(Data_Hashtags!$F$2:$F$457,Data_Hashtags!$C$2:$C$457,$A70,Data_Hashtags!$B$2:$B$457,Calc!$B$1,Data_Hashtags!$D$2:$D$457,Calc!$B$2),0) -> 152.575 | E70: =IFERROR(B70/SUM($B$70:$B$74),0) -> 0.1754386
A71: #MyntraFashion | B71: =COUNTIFS(Data_Hashtags!$C$2:$C$457,$A71,Data_Hashtags!$B$2:$B$457,Calc!$B$1,Data_Hashtags!$D$2:$D$457,Calc!$B$2) -> 83 | C71: =IFERROR(AVERAGEIFS(Data_Hashtags!$E$2:$E$457,Data_Hashtags!$C$2:$C$457,$A71,Data_Hashtags!$B$2:$B$457,Calc!$B$1,Data_Hashtags!$D$2:$D$457,Calc!$B$2),0) -> 0.14549347 | D71: =IFERROR(AVERAGEIFS(Data_Hashtags!$F$2:$F$457,Data_Hashtags!$C$2:$C$457,$A71,Data_Hashtags!$B$2:$B$457,Calc!$B$1,Data_Hashtags!$D$2:$D$457,Calc!$B$2),0) -> 140.96386 | E71: =IFERROR(B71/SUM($B$70:$B$74),0) -> 0.18201754
A72: #MyntraSale | B72: =COUNTIFS(Data_Hashtags!$C$2:$C$457,$A72,Data_Hashtags!$B$2:$B$457,Calc!$B$1,Data_Hashtags!$D$2:$D$457,Calc!$B$2) -> 97 | C72: =IFERROR(AVERAGEIFS(Data_Hashtags!$E$2:$E$457,Data_Hashtags!$C$2:$C$457,$A72,Data_Hashtags!$B$2:$B$457,Calc!$B$1,Data_Hashtags!$D$2:$D$457,Calc!$B$2),0) -> 0.14917346 | D72: =IFERROR(AVERAGEIFS(Data_Hashtags!$F$2:$F$457,Data_Hashtags!$C$2:$C$457,$A72,Data_Hashtags!$B$2:$B$457,Calc!$B$1,Data_Hashtags!$D$2:$D$457,Calc!$B$2),0) -> 149.70103 | E72: =IFERROR(B72/SUM($B$70:$B$74),0) -> 0.2127193
A73: #MyntraTrend | B73: =COUNTIFS(Data_Hashtags!$C$2:$C$457,$A73,Data_Hashtags!$B$2:$B$457,Calc!$B$1,Data_Hashtags!$D$2:$D$457,Calc!$B$2) -> 92 | C73: =IFERROR(AVERAGEIFS(Data_Hashtags!$E$2:$E$457,Data_Hashtags!$C$2:$C$457,$A73,Data_Hashtags!$B$2:$B$457,Calc!$B$1,Data_Hashtags!$D$2:$D$457,Calc!$B$2),0) -> 0.1435307 | D73: =IFERROR(AVERAGEIFS(Data_Hashtags!$F$2:$F$457,Data_Hashtags!$C$2:$C$457,$A73,Data_Hashtags!$B$2:$B$457,Calc!$B$1,Data_Hashtags!$D$2:$D$457,Calc!$B$2),0) -> 165.27174 | E73: =IFERROR(B73/SUM($B$70:$B$74),0) -> 0.20175439
A74: #StyleWithMyntra | B74: =COUNTIFS(Data_Hashtags!$C$2:$C$457,$A74,Data_Hashtags!$B$2:$B$457,Calc!$B$1,Data_Hashtags!$D$2:$D$457,Calc!$B$2) -> 104 | C74: =IFERROR(AVERAGEIFS(Data_Hashtags!$E$2:$E$457,Data_Hashtags!$C$2:$C$457,$A74,Data_Hashtags!$B$2:$B$457,Calc!$B$1,Data_Hashtags!$D$2:$D$457,Calc!$B$2),0) -> 0.15618194 | D74: =IFERROR(AVERAGEIFS(Data_Hashtags!$F$2:$F$457,Data_Hashtags!$C$2:$C$457,$A74,Data_Hashtags!$B$2:$B$457,Calc!$B$1,Data_Hashtags!$D$2:$D$457,Calc!$B$2),0) -> 146.16346 | E74: =IFERROR(B74/SUM($B$70:$B$74),0) -> 0.22807018
A75: Built from the split-hashtag table (one row per post-hashtag pair), so a post with two hashtags counts once under each. Follows both filters.
A93: 4. Campaign effectiveness
A94: Campaign | B94: Start | C94: End | D94: Budget | E94: Tagged Posts | F94: Impressions | G94: Likes | H94: Clicks | I94: Avg Post Engagement Rate | J94: Total Engagement | K94: Engagement per 1,000 Budget | L94: Weeks in Window | M94: Net Followers in Window | N94: Net Followers per 1,000 Budget
A95: =Data_Campaigns!A2 -> EndOfSeasonSale | B95: =Data_Campaigns!B2 -> 45453 | C95: =Data_Campaigns!C2 -> 45478 | D95: =Data_Campaigns!E2 -> 180000 | E95: =COUNTIFS(Data_Posts!$N$2:$N$301,$A95,Data_Posts!$B$2:$B$301,Calc!$B$1) -> 83 | F95: =SUMIFS(Data_Posts!$I$2:$I$301,Data_Posts!$N$2:$N$301,$A95,Data_Posts!$B$2:$B$301,Calc!$B$1) -> 2886292 | G95: =SUMIFS(Data_Posts!$F$2:$F$301,Data_Posts!$N$2:$N$301,$A95,Data_Posts!$B$2:$B$301,Calc!$B$1) -> 232785 | H95: =SUMIFS(Data_Posts!$K$2:$K$301,Data_Posts!$N$2:$N$301,$A95,Data_Posts!$B$2:$B$301,Calc!$B$1) -> 12376 | I95: =IFERROR(AVERAGEIFS(Data_Posts!$P$2:$P$301,Data_Posts!$N$2:$N$301,$A95,Data_Posts!$B$2:$B$301,Calc!$B$1),0) -> 0.15353197 | J95: =SUMIFS(Data_Posts!$O$2:$O$301,Data_Posts!$N$2:$N$301,$A95,Data_Posts!$B$2:$B$301,Calc!$B$1) -> 295774 | K95: =IFERROR(J95/D95*1000,0) -> 1643.1889 | L95: =COUNTIFS(Calc!$A$5:$A$54,">="&B95,Calc!$A$5:$A$54,"<="&C95) -> 4 | M95: =SUMIFS(Data_Weekly!$H$2:$H$201,Data_Weekly!$A$2:$A$201,">="&B95,Data_Weekly!$A$2:$A$201,"<="&C95,Data_Weekly!$B$2:$B$201,Calc!$B$1) -> 11191 | N95: =IFERROR(M95/D95*1000,0) -> 62.172222
...

Sheet Data_Posts
A1: Post ID | B1: Platform | C1: Date | D1: Content Type | E1: Post Text | F1: Likes | G1: Shares | H1: Comments | I1: Impressions | J1: Reach | K1: Clicks | L1: Hashtag 1 | M1: Hashtag 2 | N1: Campaign | O1: Engagement | P1: Engagement Rate
A2: P001 | B2: Twitter | C2: 45649 | D2: Reel | E2: Explore the latest reel on Myntra! Trendy styles await. | F2: 1461 | G2: 184 | H2: 344 | I2: 21915 | J2: 21675 | K2: 15 | L2: #MyntraSale | N2: FashionUpgrade | O2: =F2+G2+H2 -> 1989 | P2: =IFERROR(O2/I2,0) -> 0.090759754
A3: P002 | B3: Twitter | C3: 45750 | D3: Text | E3: Explore the latest text on Myntra! Trendy styles await. | F3: 4054 | G3: 389 | H3: 493 | I3: 64864 | J3: 64383 | K3: 117 | L3: #MyntraFashion | N3: EndOfSeasonSale | O3: =F3+G3+H3 -> 4936 | P3: =IFERROR(O3/I3,0) -> 0.076097681
A4: P003 | B4: YouTube | C4: 45789 | D4: Reel | E4: Explore the latest reel on Myntra! Trendy styles await. | F4: 2795 | G4: 105 | H4: 49 | I4: 53105 | J4: 52307 | K4: 204 | L4: #MyntraFashion | M4: #MyntraSale | N4: FashionUpgrade | O4: =F4+G4+H4 -> 2949 | P4: =IFERROR(O4/I4,0) -> 0.055531494
A5: P004 | B5: Instagram | C5: 45516 | D5: Story | E5: Explore the latest story on Myntra! Trendy styles await. | F5: 2404 | G5: 363 | H5: 138 | I5: 19232 | J5: 18636 | K5: 128 | L5: #MyntraSale | N5: FashionUpgrade | O5: =F5+G5+H5 -> 2905 | P5: =IFERROR(O5/I5,0) -> 0.15105033
A6: P005 | B6: YouTube | C6: 45469 | D6: Reel | E6: Explore the latest reel on Myntra! Trendy styles await. | F6: 3557 | G6: 687 | H6: 424 | I6: 71140 | J6: 70701 | K6: 224 | L6: #StyleWithMyntra | M6: #MyntraFashion | N6: MyntraFestiveEdit | O6: =F6+G6+H6 -> 4668 | P6: =IFERROR(O6/I6,0) -> 0.065617093
A7: P006 | B7: Facebook | C7: 45596 | D7: Carousel | E7: Explore the latest carousel on Myntra! Trendy styles await. | F7: 2945 | G7: 930 | H7: 355 | I7: 23560 | J7: 23275 | K7: 256 | L7: #MyntraTrend | N7: EndOfSeasonSale | O7: =F7+G7+H7 -> 4230 | P7: =IFERROR(O7/I7,0) -> 0.1795416
A8: P007 | B8: Twitter | C8: 45467 | D8: Carousel | E8: Explore the latest carousel on Myntra! Trendy styles await. | F8: 3860 | G8: 201 | H8: 279 | I8: 61760 | J8: 61660 | K8: 235 | L8: #MyntraTrend | N8: MyntraFestiveEdit | O8: =F8+G8+H8 -> 4340 | P8: =IFERROR(O8/I8,0) -> 0.070272021
A9: P008 | B9: YouTube | C9: 45486 | D9: Image | E9: Explore the latest image on Myntra! Trendy styles await. | F9: 3929 | G9: 262 | H9: 278 | I9: 43219 | J9: 42841 | K9: 39 | L9: #MyntraFashion | M9: #MyntraSale | N9: MyntraFestiveEdit | O9: =F9+G9+H9 -> 4469 | P9: =IFERROR(O9/I9,0) -> 0.1034036
A10: P009 | B10: Facebook | C10: 45534 | D10: Text | E10: Explore the latest text on Myntra! Trendy styles await. | F10: 3784 | G10: 808 | H10: 404 | I10: 56760 | J10: 56343 | K10: 131 | L10: #MyntraFashion | M10: #MyntraSale | N10: MyntraFestiveEdit | O10: =F10+G10+H10 -> 4996 | P10: =IFERROR(O10/I10,0) -> 0.088019732
A11: P010 | B11: Facebook | C11: 45727 | D11: Image | E11: Explore the latest image on Myntra! Trendy styles await. | F11: 4241 | G11: 902 | H11: 47 | I11: 72097 | J11: 71598 | K11: 167 | L11: #MyntraTrend | N11: StyleRevolution | O11: =F11+G11+H11 -> 5190 | P11: =IFERROR(O11/I11,0) -> 0.071986352
A12: P011 | B12: Instagram | C12: 45690 | D12: Story | E12: Explore the latest story on Myntra! Trendy styles await. | F12: 1792 | G12: 614 | H12: 497 | I12: 25088 | J12: 24675 | K12: 65 | L12: #StyleWithMyntra | N12: FashionUpgrade | O12: =F12+G12+H12 -> 2903 | P12: =IFERROR(O12/I12,0) -> 0.11571269
A13: P012 | B13: Facebook | C13: 45494 | D13: Reel | E13: Explore the latest reel on Myntra! Trendy styles await. | F13: 1946 | G13: 686 | H13: 377 | I13: 23352 | J13: 22982 | K13: 213 | L13: #StyleWithMyntra | M13: #MyntraSale | N13: MyntraFestiveEdit | O13: =F13+G13+H13 -> 3009 | P13: =IFERROR(O13/I13,0) -> 0.12885406
A14: P013 | B14: YouTube | C14: 45614 | D14: Carousel | E14: Explore the latest carousel on Myntra! Trendy styles await. | F14: 1171 | G14: 286 | H14: 231 | I14: 22249 | J14: 21282 | K14: 114 | L14: #MyntraFashion | N14: StyleRevolution | O14: =F14+G14+H14 -> 1688 | P14: =IFERROR(O14/I14,0) -> 0.075868578
A15: P014 | B15: Facebook | C15: 45704 | D15: Story | E15: Explore the latest story on Myntra! Trendy styles await. | F15: 4242 | G15: 555 | H15: 131 | I15: 33936 | J15: 33802 | K15: 265 | L15: #MyntraSale | M15: #MyntraFashion | N15: MyntraFestiveEdit | O15: =F15+G15+H15 -> 4928 | P15: =IFERROR(O15/I15,0) -> 0.14521452
A16: P015 | B16: Facebook | C16: 45589 | D16: Video | E16: Explore the latest video on Myntra! Trendy styles await. | F16: 3888 | G16: 604 | H16: 128 | I16: 77760 | J16: 77167 | K16: 20 | L16: #MyntraFashion | M16: #FashionDeals | N16: FashionUpgrade | O16: =F16+G16+H16 -> 4620 | P16: =IFERROR(O16/I16,0) -> 0.05941358
A17: P016 | B17: Facebook | C17: 45530 | D17: Text | E17: Explore the latest text on Myntra! Trendy styles await. | F17: 3452 | G17: 377 | H17: 360 | I17: 55232 | J17: 55075 | K17: 87 | L17: #MyntraSale | M17: #FashionDeals | N17: MyntraFestiveEdit | O17: =F17+G17+H17 -> 4189 | P17: =IFERROR(O17/I17,0) -> 0.075843714
A18: P017 | B18: Facebook | C18: 45782 | D18: Text | E18: Explore the latest text on Myntra! Trendy styles await. | F18: 4441 | G18: 511 | H18: 70 | I18: 53292 | J18: 53082 | K18: 159 | L18: #FashionDeals | N18: MyntraFestiveEdit | O18: =F18+G18+H18 -> 5022 | P18: =IFERROR(O18/I18,0) -> 0.094235533
A19: P018 | B19: Instagram | C19: 45523 | D19: Reel | E19: Explore the latest reel on Myntra! Trendy styles await. | F19: 3000 | G19: 382 | H19: 325 | I19: 36000 | J19: 35819 | K19: 19 | L19: #StyleWithMyntra | N19: EndOfSeasonSale | O19: =F19+G19+H19 -> 3707 | P19: =IFERROR(O19/I19,0) -> 0.10297222
A20: P019 | B20: Instagram | C20: 45466 | D20: Video | E20: Explore the latest video on Myntra! Trendy styles await. | F20: 1071 | G20: 519 | H20: 22 | I20: 16065 | J20: 15865 | K20: 103 | L20: #MyntraSale | M20: #StyleWithMyntra | N20: MyntraFestiveEdit | O20: =F20+G20+H20 -> 1612 | P20: =IFERROR(O20/I20,0) -> 0.10034236
A21: P020 | B21: Instagram | C21: 45544 | D21: Carousel | E21: Explore the latest carousel on Myntra! Trendy styles await. | F21: 4054 | G21: 488 | H21: 373 | I21: 77026 | J21: 76881 | K21: 25 | L21: #MyntraFashion | M21: #MyntraSale | N21: MyntraFestiveEdit | O21: =F21+G21+H21 -> 4915 | P21: =IFERROR(O21/I21,0) -> 0.063809623
A22: P021 | B22: Instagram | C22: 45661 | D22: Reel | E22: Explore the latest reel on Myntra! Trendy styles await. | F22: 4838 | G22: 640 | H22: 128 | I22: 72570 | J22: 72396 | K22: 83 | L22: #StyleWithMyntra | M22: #MyntraTrend | N22: MyntraFestiveEdit | O22: =F22+G22+H22 -> 5606 | P22: =IFERROR(O22/I22,0) -> 0.077249552
A23: P022 | B23: Facebook | C23: 45715 | D23: Text | E23: Explore the latest text on Myntra! Trendy styles await. | F23: 1570 | G23: 187 | H23: 260 | I23: 25120 | J23: 24613 | K23: 133 | L23: #MyntraSale | N23: StyleRevolution | O23: =F23+G23+H23 -> 2017 | P23: =IFERROR(O23/I23,0) -> 0.080294586
A24: P023 | B24: Facebook | C24: 45602 | D24: Video | E24: Explore the latest video on Myntra! Trendy styles await. | F24: 1606 | G24: 547 | H24: 316 | I24: 32120 | J24: 31736 | K24: 225 | L24: #MyntraSale | N24: MyntraFestiveEdit | O24: =F24+G24+H24 -> 2469 | P24: =IFERROR(O24/I24,0) -> 0.076867995
A25: P024 | B25: Facebook | C25: 45680 | D25: Video | E25: Explore the latest video on Myntra! Trendy styles await. | F25: 3961 | G25: 761 | H25: 131 | I25: 67337 | J25: 66615 | K25: 161 | L25: #MyntraTrend | N25: EndOfSeasonSale | O25: =F25+G25+H25 -> 4853 | P25: =IFERROR(O25/I25,0) -> 0.072070333
A26: P025 | B26: Twitter | C26: 45757 | D26: Carousel | E26: Explore the latest carousel on Myntra! Trendy styles await. | F26: 3128 | G26: 211 | H26: 197 | I26: 59432 | J26: 59182 | K26: 238 | L26: #StyleWithMyntra | M26: #MyntraSale | N26: FashionUpgrade | O26: =F26+G26+H26 -> 3536 | P26: =IFERROR(O26/I26,0) -> 0.059496568
A27: P026 | B27: YouTube | C27: 45752 | D27: Reel | E27: Explore the latest reel on Myntra! Trendy styles await. | F27: 3009 | G27: 413 | H27: 358 | I27: 42126 | J27: 41309 | K27: 211 | L27: #MyntraSale | N27: EndOfSeasonSale | O27: =F27+G27+H27 -> 3780 | P27: =IFERROR(O27/I27,0) -> 0.089730808
A28: P027 | B28: YouTube | C28: 45552 | D28: Text | E28: Explore the latest text on Myntra! Trendy styles await. | F28: 2076 | G28: 195 | H28: 104 | I28: 33216 | J28: 32244 | K28: 51 | L28: #MyntraTrend | N28: StyleRevolution | O28: =F28+G28+H28 -> 2375 | P28: =IFERROR(O28/I28,0) -> 0.071501686
A29: P028 | B29: Instagram | C29: 45720 | D29: Video | E29: Explore the latest video on Myntra! Trendy styles await. | F29: 432 | G29: 624 | H29: 123 | I29: 6912 | J29: 6259 | K29: 79 | L29: #MyntraSale | M29: #MyntraTrend | N29: EndOfSeasonSale | O29: =F29+G29+H29 -> 1179 | P29: =IFERROR(O29/I29,0) -> 0.17057292
A30: P029 | B30: Instagram | C30: 45688 | D30: Carousel | E30: Explore the latest carousel on Myntra! Trendy styles await. | F30: 2566 | G30: 118 | H30: 37 | I30: 12830 | J30: 12264 | K30: 221 | L30: #MyntraTrend | M30: #MyntraFashion | N30: MyntraFestiveEdit | O30: =F30+G30+H30 -> 2721 | P30: =IFERROR(O30/I30,0) -> 0.21208106
A31: P030 | B31: Instagram | C31: 45713 | D31: Video | E31: Explore the latest video on Myntra! Trendy styles await. | F31: 3095 | G31: 39 | H31: 78 | I31: 55710 | J31: 54808 | K31: 93 | L31: #MyntraSale | N31: StyleRevolution | O31: =F31+G31+H31 -> 3212 | P31: =IFERROR(O31/I31,0) -> 0.057655717
A32: P031 | B32: Instagram | C32: 45642 | D32: Text | E32: Explore the latest text on Myntra! Trendy styles await. | F32: 438 | G32: 153 | H32: 275 | I32: 3066 | J32: 2701 | K32: 282 | L32: #MyntraTrend | N32: StyleRevolution | O32: =F32+G32+H32 -> 866 | P32: =IFERROR(O32/I32,0) -> 0.28245271
A33: P032 | B33: Twitter | C33: 45504 | D33: Carousel | E33: Explore the latest carousel on Myntra! Trendy styles await. | F33: 2278 | G33: 10 | H33: 321 | I33: 13668 | J33: 12676 | K33: 275 | L33: #MyntraTrend | M33: #MyntraFashion | N33: StyleRevolution | O33: =F33+G33+H33 -> 2609 | P33: =IFERROR(O33/I33,0) -> 0.19088382
A34: P033 | B34: Facebook | C34: 45525 | D34: Image | E34: Explore the latest image on Myntra! Trendy styles await. | F34: 1407 | G34: 400 | H34: 351 | I34: 16884 | J34: 15954 | K34: 113 | L34: #MyntraFashion | M34: #FashionDeals | N34: MyntraFestiveEdit | O34: =F34+G34+H34 -> 2158 | P34: =IFERROR(O34/I34,0) -> 0.12781331
A35: P034 | B35: Facebook | C35: 45742 | D35: Text | E35: Explore the latest text on Myntra! Trendy styles await. | F35: 1652 | G35: 89 | H35: 357 | I35: 29736 | J35: 28771 | K35: 215 | L35: #MyntraTrend | M35: #FashionDeals | N35: EndOfSeasonSale | O35: =F35+G35+H35 -> 2098 | P35: =IFERROR(O35/I35,0) -> 0.07055421
A36: P035 | B36: Instagram | C36: 45626 | D36: Video | E36: Explore the latest video on Myntra! Trendy styles await. | F36: 3775 | G36: 16 | H36: 239 | I36: 33975 | J36: 33310 | K36: 271 | L36: #StyleWithMyntra | M36: #MyntraSale | N36: MyntraFestiveEdit | O36: =F36+G36+H36 -> 4030 | P36: =IFERROR(O36/I36,0) -> 0.11861663
A37: P036 | B37: Instagram | C37: 45766 | D37: Story | E37: Explore the latest story on Myntra! Trendy styles await. | F37: 4518 | G37: 285 | H37: 383 | I37: 67770 | J37: 67621 | K37: 31 | L37: #FashionDeals | N37: EndOfSeasonSale | O37: =F37+G37+H37 -> 5186 | P37: =IFERROR(O37/I37,0) -> 0.076523535
A38: P037 | B38: Facebook | C38: 45663 | D38: Carousel | E38: Explore the latest carousel on Myntra! Trendy styles await. | F38: 3024 | G38: 925 | H38: 350 | I38: 24192 | J38: 23518 | K38: 36 | L38: #MyntraSale | N38: MyntraFestiveEdit | O38: =F38+G38+H38 -> 4299 | P38: =IFERROR(O38/I38,0) -> 0.17770337
A39: P038 | B39: YouTube | C39: 45705 | D39: Reel | E39: Explore the latest reel on Myntra! Trendy styles await. | F39: 3138 | G39: 123 | H39: 291 | I39: 28242 | J39: 27550 | K39: 87 | L39: #FashionDeals | N39: StyleRevolution | O39: =F39+G39+H39 -> 3552 | P39: =IFERROR(O39/I39,0) -> 0.12577013
A40: P039 | B40: Facebook | C40: 45621 | D40: Image | E40: Explore the latest image on Myntra! Trendy styles await. | F40: 3564 | G40: 629 | H40: 177 | I40: 60588 | J40: 59627 | K40: 92 | L40: #FashionDeals | M40: #MyntraSale | N40: MyntraFestiveEdit | O40: =F40+G40+H40 -> 4370 | P40: =IFERROR(O40/I40,0) -> 0.072126494
...

Sheet Data_Weekly
A1: Week Start | B1: Platform | C1: New Followers | D1: Unfollows | E1: Total Followers (as supplied) | F1: Engagement Rate % (as supplied) | G1: Ad Spend | H1: Net Followers
A2: 45446 | B2: Instagram | C2: 1135 | D2: 88 | E2: 344084 | F2: 8.06 | G2: 5904 | H2: =C2-D2 -> 1047
A3: 45446 | B3: Facebook | C3: 1312 | D3: 310 | E3: 42654 | F3: 4.98 | G3: 9566 | H3: =C3-D3 -> 1002
A4: 45446 | B4: Twitter | C4: 584 | D4: 169 | E4: 146834 | F4: 8.31 | G4: 26752 | H4: =C4-D4 -> 415
A5: 45446 | B5: YouTube | C5: 1535 | D5: 445 | E5: 395536 | F5: 4.11 | G5: 30671 | H5: =C5-D5 -> 1090
A6: 45453 | B6: Instagram | C6: 656 | D6: 139 | E6: 49157 | F6: 9.05 | G6: 9920 | H6: =C6-D6 -> 517
A7: 45453 | B7: Facebook | C7: 1697 | D7: 414 | E7: 316555 | F7: 2.37 | G7: 7924 | H7: =C7-D7 -> 1283
A8: 45453 | B8: Twitter | C8: 436 | D8: 250 | E8: 254347 | F8: 4.01 | G8: 8912 | H8: =C8-D8 -> 186
A9: 45453 | B9: YouTube | C9: 1197 | D9: 203 | E9: 413878 | F9: 3.16 | G9: 21205 | H9: =C9-D9 -> 994
A10: 45460 | B10: Instagram | C10: 1048 | D10: 155 | E10: 456946 | F10: 2.46 | G10: 11329 | H10: =C10-D10 -> 893
A11: 45460 | B11: Facebook | C11: 1753 | D11: 371 | E11: 169496 | F11: 8.11 | G11: 46670 | H11: =C11-D11 -> 1382
A12: 45460 | B12: Twitter | C12: 1335 | D12: 40 | E12: 122732 | F12: 8.19 | G12: 22482 | H12: =C12-D12 -> 1295
A13: 45460 | B13: YouTube | C13: 403 | D13: 66 | E13: 382851 | F13: 3.49 | G13: 24313 | H13: =C13-D13 -> 337
... A201: 45789 | B201: YouTube | C201: 119 | D201: 456 | E201: 82558 | F201: 6.81 | G201: 12174 | H201: =C201-D201 -> -337

Sheet Data_Campaigns
A1: Campaign | B1: Start Date | C1: End Date | D1: Objective | E1: Total Budget | F1: Target Platforms
A2: EndOfSeasonSale | B2: 45453 | C2: 45478 | D2: Seasonal Clearance Promotion | E2: 180000 | F2: Instagram,Facebook
A3: FashionUpgrade | B3: 45505 | C3: 45535 | D3: Customer Engagement | E3: 160000 | F3: Instagram,YouTube
A4: MyntraFestiveEdit | B4: 45570 | C4: 45601 | D4: Festive Collection Launch | E4: 220000 | F4: Facebook,Instagram
A5: StyleRevolution | B5: 45667 | C5: 45698 | D5: Brand Awareness & Growth | E5: 200000 | F5: Instagram,Twitter

Sheet Data_Hashtags
A1: Post ID | B1: Platform | C1: Hashtag | D1: Campaign | E1: Engagement Rate | F1: Clicks
A2: P001 | B2: Twitter | C2: #MyntraSale | D2: =INDEX(Data_Posts!$N$2:$N$301,MATCH(A2,Data_Posts!$A$2:$A$301,0)) -> FashionUpgrade | E2: =INDEX(Data_Posts!$P$2:$P$301,MATCH(A2,Data_Posts!$A$2:$A$301,0)) -> 0.090759754 | F2: =INDEX(Data_Posts!$K$2:$K$301,MATCH(A2,Data_Posts!$A$2:$A$301,0)) -> 15
A3: P002 | B3: Twitter | C3: #MyntraFashion | D3: =INDEX(Data_Posts!$N$2:$N$301,MATCH(A3,Data_Posts!$A$2:$A$301,0)) -> EndOfSeasonSale | E3: =INDEX(Data_Posts!$P$2:$P$301,MATCH(A3,Data_Posts!$A$2:$A$301,0)) -> 0.076097681 | F3: =INDEX(Data_Posts!$K$2:$K$301,MATCH(A3,Data_Posts!$A$2:$A$301,0)) -> 117
A4: P003 | B4: YouTube | C4: #MyntraFashion | D4: =INDEX(Data_Posts!$N$2:$N$301,MATCH(A4,Data_Posts!$A$2:$A$301,0)) -> FashionUpgrade | E4: =INDEX(Data_Posts!$P$2:$P$301,MATCH(A4,Data_Posts!$A$2:$A$301,0)) -> 0.055531494 | F4: =INDEX(Data_Posts!$K$2:$K$301,MATCH(A4,Data_Posts!$A$2:$A$301,0)) -> 204
A5: P003 | B5: YouTube | C5: #MyntraSale | D5: =INDEX(Data_Posts!$N$2:$N$301,MATCH(A5,Data_Posts!$A$2:$A$301,0)) -> FashionUpgrade | E5: =INDEX(Data_Posts!$P$2:$P$301,MATCH(A5,Data_Posts!$A$2:$A$301,0)) -> 0.055531494 | F5: =INDEX(Data_Posts!$K$2:$K$301,MATCH(A5,Data_Posts!$A$2:$A$301,0)) -> 204
A6: P004 | B6: Instagram | C6: #MyntraSale | D6: =INDEX(Data_Posts!$N$2:$N$301,MATCH(A6,Data_Posts!$A$2:$A$301,0)) -> FashionUpgrade | E6: =INDEX(Data_Posts!$P$2:$P$301,MATCH(A6,Data_Posts!$A$2:$A$301,0)) -> 0.15105033 | F6: =INDEX(Data_Posts!$K$2:$K$301,MATCH(A6,Data_Posts!$A$2:$A$301,0)) -> 128
A7: P005 | B7: YouTube | C7: #StyleWithMyntra | D7: =INDEX(Data_Posts!$N$2:$N$301,MATCH(A7,Data_Posts!$A$2:$A$301,0)) -> MyntraFestiveEdit | E7: =INDEX(Data_Posts!$P$2:$P$301,MATCH(A7,Data_Posts!$A$2:$A$301,0)) -> 0.065617093 | F7: =INDEX(Data_Posts!$K$2:$K$301,MATCH(A7,Data_Posts!$A$2:$A$301,0)) -> 224
A8: P005 | B8: YouTube | C8: #MyntraFashion | D8: =INDEX(Data_Posts!$N$2:$N$301,MATCH(A8,Data_Posts!$A$2:$A$301,0)) -> MyntraFestiveEdit | E8: =INDEX(Data_Posts!$P$2:$P$301,MATCH(A8,Data_Posts!$A$2:$A$301,0)) -> 0.065617093 | F8: =INDEX(Data_Posts!$K$2:$K$301,MATCH(A8,Data_Posts!$A$2:$A$301,0)) -> 224
A9: P006 | B9: Facebook | C9: #MyntraTrend | D9: =INDEX(Data_Posts!$N$2:$N$301,MATCH(A9,Data_Posts!$A$2:$A$301,0)) -> EndOfSeasonSale | E9: =INDEX(Data_Posts!$P$2:$P$301,MATCH(A9,Data_Posts!$A$2:$A$301,0)) -> 0.1795416 | F9: =INDEX(Data_Posts!$K$2:$K$301,MATCH(A9,Data_Posts!$A$2:$A$301,0)) -> 256
A10: P007 | B10: Twitter | C10: #MyntraTrend | D10: =INDEX(Data_Posts!$N$2:$N$301,MATCH(A10,Data_Posts!$A$2:$A$301,0)) -> MyntraFestiveEdit | E10: =INDEX(Data_Posts!$P$2:$P$301,MATCH(A10,Data_Posts!$A$2:$A$301,0)) -> 0.070272021 | F10: =INDEX(Data_Posts!$K$2:$K$301,MATCH(A10,Data_Posts!$A$2:$A$301,0)) -> 235
A11: P008 | B11: YouTube | C11: #MyntraFashion | D11: =INDEX(Data_Posts!$N$2:$N$301,MATCH(A11,Data_Posts!$A$2:$A$301,0)) -> MyntraFestiveEdit | E11: =INDEX(Data_Posts!$P$2:$P$301,MATCH(A11,Data_Posts!$A$2:$A$301,0)) -> 0.1034036 | F11: =INDEX(Data_Posts!$K$2:$K$301,MATCH(A11,Data_Posts!$A$2:$A$301,0)) -> 39
A12: P008 | B12: YouTube | C12: #MyntraSale | D12: =INDEX(Data_Posts!$N$2:$N$301,MATCH(A12,Data_Posts!$A$2:$A$301,0)) -> MyntraFestiveEdit | E12: =INDEX(Data_Posts!$P$2:$P$301,MATCH(A12,Data_Posts!$A$2:$A$301,0)) -> 0.1034036 | F12: =INDEX(Data_Posts!$K$2:$K$301,MATCH(A12,Data_Posts!$A$2:$A$301,0)) -> 39
A13: P009 | B13: Facebook | C13: #MyntraFashion | D13: =INDEX(Data_Posts!$N$2:$N$301,MATCH(A13,Data_Posts!$A$2:$A$301,0)) -> MyntraFestiveEdit | E13: =INDEX(Data_Posts!$P$2:$P$301,MATCH(A13,Data_Posts!$A$2:$A$301,0)) -> 0.088019732 | F13: =INDEX(Data_Posts!$K$2:$K$301,MATCH(A13,Data_Posts!$A$2:$A$301,0)) -> 131
... A457: P300 | B457: Twitter | C457: #MyntraFashion | D457: =INDEX(Data_Posts!$N$2:$N$301,MATCH(A457,Data_Posts!$A$2:$A$301,0)) -> FashionUpgrade | E457: =INDEX(Data_Posts!$P$2:$P$301,MATCH(A457,Data_Posts!$A$2:$A$301,0)) -> 0.083539958 | F457: =INDEX(Data_Posts!$K$2:$K$301,MATCH(A457,Data_Posts!$A$2:$A$301,0)) -> 191

Sheet Calc
A1: Platform criterion | B1: =IF(Dashboard!$C$4="All","*",Dashboard!$C$4) -> * | D1: Weekly trend table (feeds the trend charts). First week is the first Monday in the weekly data; each next row adds 7 days.
A2: Campaign criterion | B2: =IF(Dashboard!$F$4="All","*",Dashboard!$F$4) -> *
A4: Week Start | B4: Net Followers Added | C4: 4-wk Moving Avg | D4: Ad Spend
A5: 45446 | B5: =SUMIFS(Data_Weekly!$H$2:$H$201,Data_Weekly!$A$2:$A$201,A5,Data_Weekly!$B$2:$B$201,Calc!$B$1) -> 3554 | C5: =AVERAGE(B5:B5) -> 3554 | D5: =SUMIFS(Data_Weekly!$G$2:$G$201,Data_Weekly!$A$2:$A$201,A5,Data_Weekly!$B$2:$B$201,Calc!$B$1) -> 72893
A6: =A5+7 -> 45453 | B6: =SUMIFS(Data_Weekly!$H$2:$H$201,Data_Weekly!$A$2:$A$201,A6,Data_Weekly!$B$2:$B$201,Calc!$B$1) -> 2980 | C6: =AVERAGE(B5:B6) -> 3267 | D6: =SUMIFS(Data_Weekly!$G$2:$G$201,Data_Weekly!$A$2:$A$201,A6,Data_Weekly!$B$2:$B$201,Calc!$B$1) -> 47961
A7: =A6+7 -> 45460 | B7: =SUMIFS(Data_Weekly!$H$2:$H$201,Data_Weekly!$A$2:$A$201,A7,Data_Weekly!$B$2:$B$201,Calc!$B$1) -> 3907 | C7: =AVERAGE(B5:B7) -> 3480.3333 | D7: =SUMIFS(Data_Weekly!$G$2:$G$201,Data_Weekly!$A$2:$A$201,A7,Data_Weekly!$B$2:$B$201,Calc!$B$1) -> 104794
A8: =A7+7 -> 45467 | B8: =SUMIFS(Data_Weekly!$H$2:$H$201,Data_Weekly!$A$2:$A$201,A8,Data_Weekly!$B$2:$B$201,Calc!$B$1) -> 3011 | C8: =AVERAGE(B5:B8) -> 3363 | D8: =SUMIFS(Data_Weekly!$G$2:$G$201,Data_Weekly!$A$2:$A$201,A8,Data_Weekly!$B$2:$B$201,Calc!$B$1) -> 81748
A9: =A8+7 -> 45474 | B9: =SUMIFS(Data_Weekly!$H$2:$H$201,Data_Weekly!$A$2:$A$201,A9,Data_Weekly!$B$2:$B$201,Calc!$B$1) -> 1293 | C9: =AVERAGE(B6:B9) -> 2797.75 | D9: =SUMIFS(Data_Weekly!$G$2:$G$201,Data_Weekly!$A$2:$A$201,A9,Data_Weekly!$B$2:$B$201,Calc!$B$1) -> 87847
A10: =A9+7 -> 45481 | B10: =SUMIFS(Data_Weekly!$H$2:$H$201,Data_Weekly!$A$2:$A$201,A10,Data_Weekly!$B$2:$B$201,Calc!$B$1) -> 3042 | C10: =AVERAGE(B7:B10) -> 2813.25 | D10: =SUMIFS(Data_Weekly!$G$2:$G$201,Data_Weekly!$A$2:$A$201,A10,Data_Weekly!$B$2:$B$201,Calc!$B$1) -> 79341
A11: =A10+7 -> 45488 | B11: =SUMIFS(Data_Weekly!$H$2:$H$201,Data_Weekly!$A$2:$A$201,A11,Data_Weekly!$B$2:$B$201,Calc!$B$1) -> 2270 | C11: =AVERAGE(B8:B11) -> 2404 | D11: =SUMIFS(Data_Weekly!$G$2:$G$201,Data_Weekly!$A$2:$A$201,A11,Data_Weekly!$B$2:$B$201,Calc!$B$1) -> 115027
A12: =A11+7 -> 45495 | B12: =SUMIFS(Data_Weekly!$H$2:$H$201,Data_Weekly!$A$2:$A$201,A12,Data_Weekly!$B$2:$B$201,Calc!$B$1) -> 2753 | C12: =AVERAGE(B9:B12) -> 2339.5 | D12: =SUMIFS(Data_Weekly!$G$2:$G$201,Data_Weekly!$A$2:$A$201,A12,Data_Weekly!$B$2:$B$201,Calc!$B$1) -> 102610
A13: =A12+7 -> 45502 | B13: =SUMIFS(Data_Weekly!$H$2:$H$201,Data_Weekly!$A$2:$A$201,A13,Data_Weekly!$B$2:$B$201,Calc!$B$1) -> 2193 | C13: =AVERAGE(B10:B13) -> 2564.5 | D13: =SUMIFS(Data_Weekly!$G$2:$G$201,Data_Weekly!$A$2:$A$201,A13,Data_Weekly!$B$2:$B$201,Calc!$B$1) -> 76268
A14: =A13+7 -> 45509 | B14: =SUMIFS(Data_Weekly!$H$2:$H$201,Data_Weekly!$A$2:$A$201,A14,Data_Weekly!$B$2:$B$201,Calc!$B$1) -> 802 | C14: =AVERAGE(B11:B14) -> 2004.5 | D14: =SUMIFS(Data_Weekly!$G$2:$G$201,Data_Weekly!$A$2:$A$201,A14,Data_Weekly!$B$2:$B$201,Calc!$B$1) -> 137514
A15: =A14+7 -> 45516 | B15: =SUMIFS(Data_Weekly!$H$2:$H$201,Data_Weekly!$A$2:$A$201,A15,Data_Weekly!$B$2:$B$201,Calc!$B$1) -> 3728 | C15: =AVERAGE(B12:B15) -> 2369 | D15: =SUMIFS(Data_Weekly!$G$2:$G$201,Data_Weekly!$A$2:$A$201,A15,Data_Weekly!$B$2:$B$201,Calc!$B$1) -> 125177
A16: =A15+7 -> 45523 | B16: =SUMIFS(Data_Weekly!$H$2:$H$201,Data_Weekly!$A$2:$A$201,A16,Data_Weekly!$B$2:$B$201,Calc!$B$1) -> 2989 | C16: =AVERAGE(B13:B16) -> 2428 | D16: =SUMIFS(Data_Weekly!$G$2:$G$201,Data_Weekly!$A$2:$A$201,A16,Data_Weekly!$B$2:$B$201,Calc!$B$1) -> 82193
A17: =A16+7 -> 45530 | B17: =SUMIFS(Data_Weekly!$H$2:$H$201,Data_Weekly!$A$2:$A$201,A17,Data_Weekly!$B$2:$B$201,Calc!$B$1) -> 2903 | C17: =AVERAGE(B14:B17) -> 2605.5 | D17: =SUMIFS(Data_Weekly!$G$2:$G$201,Data_Weekly!$A$2:$A$201,A17,Data_Weekly!$B$2:$B$201,Calc!$B$1) -> 94709
A18: =A17+7 -> 45537 | B18: =SUMIFS(Data_Weekly!$H$2:$H$201,Data_Weekly!$A$2:$A$201,A18,Data_Weekly!$B$2:$B$201,Calc!$B$1) -> 2822 | C18: =AVERAGE(B15:B18) -> 3110.5 | D18: =SUMIFS(Data_Weekly!$G$2:$G$201,Data_Weekly!$A$2:$A$201,A18,Data_Weekly!$B$2:$B$201,Calc!$B$1) -> 100656
A19: =A18+7 -> 45544 | B19: =SUMIFS(Data_Weekly!$H$2:$H$201,Data_Weekly!$A$2:$A$201,A19,Data_Weekly!$B$2:$B$201,Calc!$B$1) -> 4360 | C19: =AVERAGE(B16:B19) -> 3268.5 | D19: =SUMIFS(Data_Weekly!$G$2:$G$201,Data_Weekly!$A$2:$A$201,A19,Data_Weekly!$B$2:$B$201,Calc!$B$1) -> 92834
... A54: =A53+7 -> 45789 | B54: =SUMIFS(Data_Weekly!$H$2:$H$201,Data_Weekly!$A$2:$A$201,A54,Data_Weekly!$B$2:$B$201,Calc!$B$1) -> 1995 | C54: =AVERAGE(B51:B54) -> 3551.5 | D54: =SUMIFS(Data_Weekly!$G$2:$G$201,Data_Weekly!$A$2:$A$201,A54,Data_Weekly!$B$2:$B$201,Calc!$B$1) -> 85623
A56: Moving average uses an expanding window for the first three weeks, then a 4-week trailing window.

Sheet Notes
A1: About this workbook
A2: Purpose | B2: One-page view of the Myntra social media analysis (Tasks 1-6), rebuilt on the cleaned data from the Task 1 workbook.
A3: How to use | B3: Change the yellow Platform and Campaign cells on the Dashboard. Everything recalculates from the Data_ sheets with formulas.
A5: Metric definitions
A6: Engagement | B6: Likes + Shares + Comments (per the project brief).
A7: Avg post engagement rate | B7: Average of each post's (Likes + Shares + Comments) / Impressions. This is the brief's definition.
A8: Pooled engagement rate | B8: Total engagement / total impressions. Less sensitive to tiny-impression posts, so it is shown next to the average.
A9: CTR | B9: Total clicks / total impressions.
A10: Net followers | B10: New_Followers - Unfollows from the weekly summary.
A11: Per 1,000 ad spend / budget | B11: Value divided by spend (or campaign budget), multiplied by 1,000.
A13: Assumptions and data caveats
A14: Total_Followers not used | B14: The supplied Total_Followers column jumps by hundreds of thousands between weeks (e.g. Facebook 42,654 to 316,555 to 169,496), so growth is measured from net adds instead. The column is kept in Data_Weekly for reference.
A15: Ad spend currency | B15: Not stated in the source data, so no currency symbol is shown.
A16: Campaign tags vs dates | B16: Posts carry a campaign tag, but post dates span the whole year regardless of campaign dates. Post-based campaign metrics use the tag; follower metrics use the campaign date window. They are not directly comparable.
A17: Outliers | B17: A few posts have impressions lower than their shares, giving engagement rates above 100% (maximum about 181%). They are kept, as in the original analysis, and the pooled rate is provided as a check.
A18: Small samples | B18: Content type x platform cells hold about 12 posts each; differences between them are directional, not statistically tested.
A19: No duplicates found | B19: All 300 Post IDs in the source are unique, so no rows were removed.
A20: Weekly data | B20: 200 rows = 50 weeks x 4 platforms (weeks starting 3 Jun 2024 to 12 May 2025). Weekly data has no campaign field.
A22: Source | B22: Task-1_DataCleaning.xlsx (sheets: Post, Split_Hashtags_rows, Engagment Summary, Campaign Data).
